<mujoco model="robot_right">
  <compiler eulerseq="XYZ" autolimits="true" />

  <default>
    <default class="right_arm" />
  </default>
  <asset>
    <material name="ra_material_1" class="right_arm" emission="0" specular="0"
      rgba="0.16 0.16 0.16 1" />
    <material name="ra_material_2" class="right_arm" emission="0" specular="0"
      rgba="0.16 0.16 0.16 1" />
    <material name="ra_material_3" class="right_arm" emission="0" specular="0"
      rgba="0.64 0.64 0.64 1" />
    <material name="ra_material_4" class="right_arm" emission="0" specular="0"
      rgba="0.16 0.16 0.16 1" />
    <material name="ra_material_5" class="right_arm" emission="0" specular="0"
      rgba="0.16 0.16 0.16 1" />
    <material name="ra_material_6" class="right_arm" emission="0" specular="0"
      rgba="0.16 0.16 0.16 1" />
    <material name="ra_material_7" class="right_arm" emission="0" specular="0"
      rgba="0.16 0.16 0.16 1" />
  </asset>
  <worldbody>
    <body name="ra_0" pos="0 0.1 0.05" euler="90 -60 90">
      <!-- <body name="ra_0" pos="0 0.1 0.05" euler="-90 -60 -90"> -->
      <inertial pos="0 0 0" mass="1" fullinertia="0.003 0.003 0.003 0 0 0" />
      <geom name="ra_collision" class="right_arm" type="sphere" group="3"
        size="0.05" pos="0 0 0" euler="0 -0 0" />
      <geom name="ra_ball" class="right_arm" type="sphere" group="0" size="0.05" pos="0 0 0"
        euler="0 -0 0" />
      <body name="ra_1" pos="0 0 0" euler="0 -0 0">
        <inertial pos="0 0 0" mass="0.1" fullinertia="0.003 0.003 0.003 0 0 0" />
        <geom name="ra_collision_0" class="right_arm" type="sphere" group="3"
          size="0.05" pos="0 0.10 0" euler="0 -0 0" />
        <geom name="ra_collision_1" class="right_arm" type="sphere" group="3"
          size="0.05" pos="0 0.20 0" euler="0 -0 0" />
        <geom name="ra_collision_2" class="right_arm" type="sphere" group="3"
          size="0.05" pos="0 0.30 0" euler="0 -0 0" />
        <geom name="ra_ball0" class="right_arm" type="sphere" group="0" size="0.05"
          material="ra_material_1" pos="0 0.10 0" euler="0 -0 0" />
        <geom name="ra_ball1" class="right_arm" type="sphere" group="0" size="0.05"
          material="ra_material_2" pos="0 0.20 0" euler="0 -0 0" />
        <geom name="ra_ball2" class="right_arm" type="sphere" group="0" size="0.05"
          material="ra_material_3" pos="0 0.30 0" euler="0 -0 0" />
        <geom name="ra_cylinder" class="right_arm" type="cylinder" group="0"
          size="0.05 0.05" material="ra_material_4"
          pos="0 0.150 0" euler="90 -0 0" />
        <joint name="robot:ra_joint_1" class="right_arm" type="hinge" pos="0 0 0" axis="1 0 0"
          limited="true" range="0 90" damping="0.50" />
        <body name="ra_2" pos="0 0.30 0" euler="0 -0 0">
          <inertial pos="0 0 0" mass="0.01" fullinertia="0.003 0.003 0.003 0 0 0" />
          <geom name="ra_collision_0_0" class="right_arm" type="sphere" group="3"
            size="0.05" pos="0 0.10 0" euler="0 -0 0" />
          <geom name="ra_collision_1_0" class="right_arm" type="sphere" group="3"
            size="0.05" pos="0 0.20 0" euler="0 -0 0" />
          <geom name="ra_ball0_0" class="right_arm" type="sphere" group="0"
            size="0.05" material="ra_material_5" pos="0 0.10 0"
            euler="0 -0 0" />
          <geom name="ra_ball1_0" class="right_arm" type="sphere" group="0"
            size="0.05" material="ra_material_6" pos="0 0.20 0"
            euler="0 -0 0" />
          <geom name="ra_cylinder_0" class="right_arm" type="cylinder" group="0"
            size="0.05 0.05" material="ra_material_7"
            pos="0 0.15 0" euler="90 -0 0" />
          <joint name="robot:ra_joint_2" class="right_arm" type="hinge" pos="0 0 0" axis="1 0 0"
            limited="true" range="0 137.50987083139756" damping="0.50" />
          <site name="rf_site_tip" pos="0 0 0.0" />
        </body>
      </body>
    </body>
  </worldbody>

  <actuator>
    <position class="right_arm" name="robot:ra_actuator_1" joint="robot:ra_joint_1" kp="10"
      ctrlrange="0 2.1" />
    <position class="right_arm" name="robot:ra_actuator_2" joint="robot:ra_joint_2" kp="5"
      ctrlrange="0 2.1" />
  </actuator>
</mujoco>