<!--
 ~ Copyright 2019 The ROBEL Authors.
 ~
 ~ Licensed under the Apache License, Version 2.0 (the "License");
 ~ you may not use this file except in compliance with the License.
 ~ You may obtain a copy of the License at
 ~
 ~     http://www.apache.org/licenses/LICENSE-2.0
 ~
 ~ Unless required by applicable law or agreed to in writing, software
 ~ distributed under the License is distributed on an "AS IS" BASIS,
 ~ WITHOUT WARRANTIES OR CONDITIONS OF ANY KIND, either express or implied.
 ~ See the License for the specific language governing permissions and
 ~ limitations under the License.
 -->

<mujoco model="dclaw">
    <compiler angle="radian" meshdir="assets"/>

    <option timestep="0.0025" iterations="50" tolerance="1e-10" solver="Newton" jacobian="dense" cone="elliptic"/>

    <asset>
        <mesh name="xh28" file="xh_base_high_poly.stl" scale=".001 .001 .001"/>
<!--        <mesh name="acrylic_circle" file="acrylic_circle.stl" scale=".12 .12 .12"/>-->
        <mesh name="plastic_finger" file="xh_finger_tip.stl" scale=".001 .001 .001"/>
        <mesh name="metal_clamping" file="xh_clamping_high_poly.stl" scale=".001 .001 .001"/>
        <mesh name="metal_clamping_small" file="xh_clamping_small_high_poly.stl" scale=".001 .001 .001"/>
        <mesh name="plastic_top" file="xh_white_top_high_poly.stl" scale=".001 .001 .001"/>
        <mesh name="xh28_hull" file="xh_base_hull.stl" scale=".001 .001 .001"/>
        <mesh name="xh28_hull_top" file="xh_base_hull_top.stl" scale=".001 .001 .001"/>
    </asset>
    <default>
        <default class="dclaw3xh">
            <joint limited="true" damping=".1" armature="0.001"/>
            <geom contype="0" conaffinity="0" condim="4" group="1" margin="0.0005" material="metal_black" type="mesh"/>
            <motor ctrlrange="-1.57 1.57" ctrllimited="true"/>
            <site group="1"/>
            <default class="overlay">
                <geom contype="0" conaffinity="0" group="3" type="mesh" material="greenish"/>
                <joint damping="100" frictionloss="100" armature="0"/>
                <site group="3"/>
            </default>
            <default class="phy_metal">
                <geom contype="1" conaffinity="1" group="4" type="mesh" rgba="0.0 0.0 1.0 .3"/>
                <site group="4"/>
            </default>
            <default class="phy_plastic">
                <geom contype="1" conaffinity="1" group="4" type="mesh" rgba="0.0 0.0 1.0 .3"
                      friction=".2 0.005 0.0001"/>
                <site group="4"/>
            </default>
        </default>
    </default>
    <asset>
        <material name="metal_black" specular="0" shininess="0" rgba="0.2 0.2 0.2 1.0"/>
        <material name="metal_grey" specular="0" shininess="0" rgba="0.5 0.5 0.5 1.0"/>
        <material name="plastic" specular="0." shininess="0" rgba="1 1 1 1"/>
        <material name="acrylic" specular="0." shininess="0" rgba="1 1 1 .2"/>
        <material name="greenish" specular="0.0" shininess="0" rgba="0.3 1 0.3 1"/>
    </asset>
    <actuator>
        <position name="FF10" kp="20" joint="FF10" class="dclaw3xh" ctrlrange="-1.35 1.35"/>
        <position name="FF11" kp="20" joint="FF11" class="dclaw3xh" ctrlrange="-1.35 1.35"/>
        <position name="FF12" kp="20" joint="FF12" class="dclaw3xh" ctrlrange="-1.35 1.35"/>
        <position name="MF20" kp="20" joint="MF20" class="dclaw3xh" ctrlrange="-1.35 1.35"/>
        <position name="MF21" kp="20" joint="MF21" class="dclaw3xh" ctrlrange="-1.35 1.35"/>
        <position name="MF22" kp="20" joint="MF22" class="dclaw3xh" ctrlrange="-1.35 1.35"/>
        <position name="TH30" kp="20" joint="TH30" class="dclaw3xh" ctrlrange="-1.35 1.35"/>
        <position name="TH31" kp="20" joint="TH31" class="dclaw3xh" ctrlrange="-1.35 1.35"/>
        <position name="TH32" kp="20" joint="TH32" class="dclaw3xh" ctrlrange="-1.35 1.35"/>
    </actuator>
    <sensor>
        <jointpos name="FF10_pos_sensor" joint="FF10"/>
        <jointpos name="FF11_pos_sensor" joint="FF11"/>
        <jointpos name="FF12_pos_sensor" joint="FF12"/>
        <jointpos name="MF20_pos_sensor" joint="MF20"/>
        <jointpos name="MF21_pos_sensor" joint="MF21"/>
        <jointpos name="MF22_pos_sensor" joint="MF22"/>
        <jointpos name="TH30_pos_sensor" joint="TH30"/>
        <jointpos name="TH31_pos_sensor" joint="TH31"/>
        <jointpos name="TH32_pos_sensor" joint="TH32"/>
        <jointvel name="FF10_velocity_sensor" joint="FF10"/>
        <jointvel name="FF11_velocity_sensor" joint="FF11"/>
        <jointvel name="FF12_velocity_sensor" joint="FF12"/>
        <jointvel name="MF20_velocity_sensor" joint="MF20"/>
        <jointvel name="MF21_velocity_sensor" joint="MF21"/>
        <jointvel name="MF22_velocity_sensor" joint="MF22"/>
        <jointvel name="TH30_velocity_sensor" joint="TH30"/>
        <jointvel name="TH31_velocity_sensor" joint="TH31"/>
        <jointvel name="TH32_velocity_sensor" joint="TH32"/>
    </sensor>


    <worldbody>
        <body name="dClaw" euler="3.14 0 0" childclass="dclaw3xh" pos="0 0 0.3">
<!--            <geom material="acrylic" mesh="acrylic_circle"/>-->
            <geom class="phy_metal" type="cylinder" size="0.075 0.004" mass=".11"/>
            <site name="S_grasp" pos="0 0 0.24" type="sphere" size="0.01" group="4"/>
            <!-- INDEX/FIRST FINGER -->
            <body name="FFbase" pos=".03 -0.062 .003" euler="0 0 .52">
                <geom mesh="xh28" pos="0 0 0.01425" euler="1.57 0 1.57"/>
                <geom class="phy_metal" type="box" pos=".012 0 0.014" size="0.024 0.0175 0.015" mass=".093"/>
                <body name="FF10" pos="0 0 0.01425" euler="0 0 3.14">
                    <geom mesh="metal_clamping" euler="0 0 1.57"/>
                    <geom mesh="metal_clamping_small" pos="0 0 0.055" euler="3.14 0 0"/>
                    <geom mesh="xh28" pos="0 0 0.068" euler="1.57 1.57 0"/>
                    <geom class="phy_metal" type="box" pos="0 0 0.056" size="0.0175 0.015 0.024" mass=".093"/>
                    <geom class="phy_metal" type="box" pos="0.0 0 0.026" size="0.0125 0.0214 0.003" mass=".003"/>
                    <geom class="phy_metal" type="box" pos="0 0.02 0.013" size="0.011 0.0012 0.016" mass=".002"/>
                    <geom class="phy_metal" type="box" pos="0 -0.02 0.013" size="0.011 0.0012 0.016" mass=".002"/>
                    <geom class="phy_metal" type="box" pos="0 0 0.033" size="0.019 0.014 0.006" mass=".005"/>
                    <joint name="FF10" type="hinge" axis="0 1 0" range="-.45 1.35"/>
                    <body name="FF11" pos="0 0 0.0675">
                        <geom mesh="metal_clamping_small" pos="0 0 0.055" euler="3.14 0 0"/>
                        <geom mesh="xh28" pos="0 0 0.0686" euler="1.57 1.57 0"/>
                        <geom mesh="metal_clamping"/>
                        <geom class="phy_metal" type="box" pos="0 0 0.056" size="0.0175 0.015 0.024" mass=".093"/>
                        <geom class="phy_metal" type="box" pos="0 0 0.026" size="0.0214 0.0125 0.003" mass=".003"/>
                        <geom class="phy_metal" type="box" pos="0.02 0 0.013" size="0.0012 0.011 0.016" mass=".002"/>
                        <geom class="phy_metal" type="box" pos="-0.02 0 0.013" size="0.0012 0.011 0.016" mass=".002"/>
                        <geom class="phy_metal" type="box" pos="0 0 0.033" size="0.019 0.014 0.006" mass=".005"/>
                        <joint name="FF11" type="hinge" axis="1 0 0" range="-2 2"/>
                        <body name="FF12" pos="0 0 0.068">
                            <geom mesh="metal_clamping"/>
                            <geom material="plastic" mesh="plastic_finger" pos="0 0 0.046"/>
                            <geom class="phy_metal" type="box" pos="0.0 0 0.026" size="0.0214 0.0125 0.003"
                                  mass=".003"/>
                            <geom class="phy_metal" type="box" pos="0.02 0 0.013" size="0.0012 0.011 0.016"
                                  mass=".002"/>
                            <geom class="phy_metal" type="box" pos="-0.02 0 0.013" size="0.0012 0.011 0.016"
                                  mass=".002"/>
                            <geom class="phy_plastic" type="capsule" pos="0 0 0.053" size="0.011 0.02" mass=".018"/>
                            <geom class="phy_plastic" type="box" pos="0 0 0.03" size="0.0245 0.014 0.003" mass=".007"/>
                            <joint name="FF12" type="hinge" axis="1 0 0" range="-2 2"/>
                            <site name="FFtip" type="sphere" pos="0 0 .076" size="0.01" rgba="1 .3 .3 1"/>
                        </body>
                    </body>
                </body>
            </body>
            <!-- MIDDLE FINGER -->
            <body name="MFbase" pos=".03 0.062 .003" euler="0 0 2.6">
                <geom mesh="xh28" pos="0 0 0.01425" euler="1.57 0 1.57"/>
                <geom class="phy_metal" type="box" pos=".012 0 0.014" size="0.024 0.0175 0.015" mass=".093"/>
                <body name="MF20" pos="0 0 0.01425" euler="0 0 3.14">
                    <geom mesh="metal_clamping" euler="0 0 1.57"/>
                    <geom mesh="metal_clamping_small" pos="0 0 0.055" euler="3.14 0 0"/>
                    <geom mesh="xh28" pos="0 0 0.068" euler="1.57 1.57 0"/>
                    <geom class="phy_metal" type="box" pos="0 0 0.056" size="0.0175 0.015 0.024" mass=".093"/>
                    <geom class="phy_metal" type="box" pos="0.0 0 0.026" size="0.0125 0.0214 0.003" mass=".003"/>
                    <geom class="phy_metal" type="box" pos="0 0.02 0.013" size="0.011 0.0012 0.016" mass=".002"/>
                    <geom class="phy_metal" type="box" pos="0 -0.02 0.013" size="0.011 0.0012 0.016" mass=".002"/>
                    <geom class="phy_metal" type="box" pos="0 0 0.033" size="0.019 0.014 0.006" mass=".005"/>
                    <joint name="MF20" type="hinge" axis="0 1 0" range="-.45 1.35"/>
                    <body name="MF21" pos="0 0 0.0675">
                        <geom mesh="metal_clamping_small" pos="0 0 0.055" euler="3.14 0 0"/>
                        <geom mesh="xh28" pos="0 0 0.0686" euler="1.57 1.57 0"/>
                        <geom mesh="metal_clamping"/>
                        <geom class="phy_metal" type="box" pos="0 0 0.056" size="0.0175 0.015 0.024" mass=".093"/>
                        <geom class="phy_metal" type="box" pos="0 0 0.026" size="0.0214 0.0125 0.003" mass=".003"/>
                        <geom class="phy_metal" type="box" pos="0.02 0 0.013" size="0.0012 0.011 0.016" mass=".002"/>
                        <geom class="phy_metal" type="box" pos="-0.02 0 0.013" size="0.0012 0.011 0.016" mass=".002"/>
                        <geom class="phy_metal" type="box" pos="0 0 0.033" size="0.019 0.014 0.006" mass=".005"/>
                        <joint name="MF21" type="hinge" axis="1 0 0" range="-2 2"/>
                        <body name="MF22" pos="0 0 0.068">
                            <geom mesh="metal_clamping"/>
                            <geom material="plastic" mesh="plastic_finger" pos="0 0 0.046"/>
                            <geom class="phy_metal" type="box" pos="0.0 0 0.026" size="0.0214 0.0125 0.003"
                                  mass=".003"/>
                            <geom class="phy_metal" type="box" pos="0.02 0 0.013" size="0.0012 0.011 0.016"
                                  mass=".002"/>
                            <geom class="phy_metal" type="box" pos="-0.02 0 0.013" size="0.0012 0.011 0.016"
                                  mass=".002"/>
                            <geom class="phy_plastic" type="capsule" pos="0 0 0.053" size="0.011 0.02" mass=".018"/>
                            <geom class="phy_plastic" type="box" pos="0 0 0.03" size="0.0245 0.014 0.003" mass=".007"/>
                            <joint name="MF22" type="hinge" axis="1 0 0" range="-2 2"/>
                            <site name="MFtip" type="sphere" pos="0 0 .076" size="0.01" rgba=".3 1 .3 1"/>
                        </body>
                    </body>
                </body>
            </body>
            <!-- THUMB -->
            <body name="THbase" pos="-.07 0 .003" euler="0 0 -1.57">
                <geom mesh="xh28" pos="0 0 0.01425" euler="1.57 0 1.57"/>
                <geom class="phy_metal" type="box" pos=".012 0 0.014" size="0.024 0.0175 0.015" mass=".093"/>
                <body name="TH30" pos="0 0 0.01425" euler="0 0 3.14">
                    <geom mesh="metal_clamping" euler="0 0 1.57"/>
                    <geom mesh="metal_clamping_small" pos="0 0 0.055" euler="3.14 0 0"/>
                    <geom mesh="xh28" pos="0 0 0.068" euler="1.57 1.57 0"/>
                    <geom class="phy_metal" type="box" pos="0 0 0.056" size="0.0175 0.015 0.024" mass=".093"/>
                    <geom class="phy_metal" type="box" pos="0.0 0 0.026" size="0.0125 0.0214 0.003" mass=".003"/>
                    <geom class="phy_metal" type="box" pos="0 0.02 0.013" size="0.011 0.0012 0.016" mass=".002"/>
                    <geom class="phy_metal" type="box" pos="0 -0.02 0.013" size="0.011 0.0012 0.016" mass=".002"/>
                    <geom class="phy_metal" type="box" pos="0 0 0.033" size="0.019 0.014 0.006" mass=".005"/>
                    <joint name="TH30" type="hinge" axis="0 1 0" range="-.45 1.35"/>
                    <body name="TH31" pos="0 0 0.0675">
                        <geom mesh="metal_clamping_small" pos="0 0 0.055" euler="3.14 0 0"/>
                        <geom mesh="xh28" pos="0 0 0.0686" euler="1.57 1.57 0"/>
                        <geom mesh="metal_clamping"/>
                        <geom class="phy_metal" type="box" pos="0 0 0.056" size="0.0175 0.015 0.024" mass=".093"/>
                        <geom class="phy_metal" type="box" pos="0 0 0.026" size="0.0214 0.0125 0.003" mass=".003"/>
                        <geom class="phy_metal" type="box" pos="0.02 0 0.013" size="0.0012 0.011 0.016" mass=".002"/>
                        <geom class="phy_metal" type="box" pos="-0.02 0 0.013" size="0.0012 0.011 0.016" mass=".002"/>
                        <geom class="phy_metal" type="box" pos="0 0 0.033" size="0.019 0.014 0.006" mass=".005"/>
                        <joint name="TH31" type="hinge" axis="1 0 0" range="-2 2"/>
                        <body name="TH32" pos="0 0 0.068">
                            <geom mesh="metal_clamping"/>
                            <geom material="plastic" mesh="plastic_finger" pos="0 0 0.046"/>
                            <geom class="phy_metal" type="box" pos="0.0 0 0.026" size="0.0214 0.0125 0.003"
                                  mass=".003"/>
                            <geom class="phy_metal" type="box" pos="0.02 0 0.013" size="0.0012 0.011 0.016"
                                  mass=".002"/>
                            <geom class="phy_metal" type="box" pos="-0.02 0 0.013" size="0.0012 0.011 0.016"
                                  mass=".002"/>
                            <geom class="phy_plastic" type="capsule" pos="0 0 0.053" size="0.011 0.02" mass=".018"/>
                            <geom class="phy_plastic" type="box" pos="0 0 0.03" size="0.0245 0.014 0.003" mass=".007"/>
                            <joint name="TH32" type="hinge" axis="1 0 0" range="-2 2"/>
                            <site name="THtip" type="sphere" pos="0 0 .076" size="0.01" rgba=".3 .3 1 1"/>
                        </body>
                    </body>
                </body>
            </body>
        </body>
    </worldbody>
</mujoco>
